I'm sorry, but an uncaught exception occurred.

While running game code:
  File "game/script.rpy", line 41, in script call
    call chapter_2 from _call_chapter_2
  File "game/scripts/Story/chapter_2.rpy", line 8, in script
    if amyHangout == True:
  File "game/scripts/Story/chapter_2.rpy", line 8, in <module>
    if amyHangout == True:
NameError: name 'amyHangout' is not defined

-- Full Traceback ------------------------------------------------------------

Full traceback:
  File "game/script.rpy", line 41, in script call
    call chapter_2 from _call_chapter_2
  File "game/scripts/Story/chapter_2.rpy", line 8, in script
    if amyHangout == True:
  File "C:\Users\Rilogator\Documents\Game Dev\RenPy\renpy-7.3.2-sdk\renpy\ast.py", line 1830, in execute
    if renpy.python.py_eval(condition):
  File "C:\Users\Rilogator\Documents\Game Dev\RenPy\renpy-7.3.2-sdk\renpy\python.py", line 2035, in py_eval
    return py_eval_bytecode(code, globals, locals)
  File "C:\Users\Rilogator\Documents\Game Dev\RenPy\renpy-7.3.2-sdk\renpy\python.py", line 2028, in py_eval_bytecode
    return eval(bytecode, globals, locals)
  File "game/scripts/Story/chapter_2.rpy", line 8, in <module>
    if amyHangout == True:
NameError: name 'amyHangout' is not defined

Windows-8-6.2.9200
Ren'Py 7.3.2.320
Gem Blast 2.0.1
Fri Oct 04 21:53:02 2019
