I'm sorry, but an uncaught exception occurred.

While running game code:
  File "game/script.rpy", line 41, in script call
    call chapter_2 from _call_chapter_2
  File "game/scripts/Character Specific/Pearl/pearl_2.rpy", line 26, in script
    P "There's no time to waste."
Exception: Sayer 'P' is not defined.

-- Full Traceback ------------------------------------------------------------

Full traceback:
  File "game/script.rpy", line 41, in script call
    call chapter_2 from _call_chapter_2
  File "game/scripts/Character Specific/Pearl/pearl_2.rpy", line 26, in script
    P "There's no time to waste."
  File "C:\Users\Rilogator\Documents\Game Dev\RenPy\renpy-7.3.2-sdk\renpy\ast.py", line 676, in execute
    who = eval_who(self.who, self.who_fast)
  File "C:\Users\Rilogator\Documents\Game Dev\RenPy\renpy-7.3.2-sdk\renpy\ast.py", line 574, in eval_who
    raise Exception("Sayer '%s' is not defined." % who.encode("utf-8"))
Exception: Sayer 'P' is not defined.

Windows-8-6.2.9200
Ren'Py 7.3.2.320
Gem Blast 1.2.2
Mon Sep 23 15:22:39 2019
